<?xml version="1.0" ?>
<!-- =================================================================================== -->
<!-- |    This document was autogenerated by xacro from ApolloRobot.urdf.xacro         | -->
<!-- |    EDITING THIS FILE BY HAND IS NOT RECOMMENDED                                 | -->
<!-- =================================================================================== -->
<robot name="apollo_robot" xmlns:body="http://playerstage.sourceforge.net/gazebo/xmlschema/#body" xmlns:controller="http://playerstage.sourceforge.net/gazebo/xmlschema/#controller" xmlns:geom="http://playerstage.sourceforge.net/gazebo/xmlschema/#geom" xmlns:interface="http://playerstage.sourceforge.net/gazebo/xmlschema/#interface" xmlns:joint="http://playerstage.sourceforge.net/gazebo/xmlschema/#slider" xmlns:sensor="http://playerstage.sourceforge.net/gazebo/xmlschema/#sensor" xmlns:xacro="http://ros.org/wiki/xacro">
  <material name="DarpaGrey">
    <color rgba="0.9 0.9 0.9 1.0"/>
  </material>
  <material name="DarpaBlue">
    <color rgba="0.0 0.5 0.5 1.0"/>
  </material>
  <link name="ORIG"/>
  <link name="BASE">
    <inertial>
      <origin rpy="0 0 0" xyz="0 0 0"/>
      <mass value="1.0"/>
      <inertia ixx="1.0" ixy="0.0" ixz="0.0" iyy="100.0" iyz="0.0" izz="1.0"/>
    </inertial>
    <visual>
      <material name="DarpaGrey"/>
      <origin rpy="0 0 3.14159265359" xyz="0 0.02 -1.305"/>
      <geometry>
        <mesh filename="package://apollo_robot_model/meshes/stand.stl"/>
      </geometry>
    </visual>
    <collision>
      <origin rpy="0 0 3.14159265359" xyz="0 0.02 -1.305"/>
      <geometry>
        <mesh filename="package://apollo_robot_model/meshes/collision/stand.stl"/>
      </geometry>
    </collision>
  </link>
  <gazebo reference="BASE">
    <material>
                PR2/Grey2
            </material>
    <turnGravityOff>
                true
            </turnGravityOff>
    <selfCollide>
                true
            </selfCollide>
  </gazebo>
  <joint name="fixedJoint" type="fixed">
    <parent link="ORIG"/>
    <child link="BASE"/>
    <origin rpy="0 0 3.14159265359" xyz="0 0.2 1.305"/>
  </joint>
  <!-- Adding Left and Right arm -->
  <joint name="L_BASE" type="fixed">
    <origin rpy="0 0 1.0471975512" xyz="0 0 0"/>
    <parent link="BASE"/>
    <child link="L_COLLARBONE"/>
  </joint>
  <link name="L_COLLARBONE">
    <inertial>
      <origin rpy="0 0 0" xyz="0 0 0"/>
      <mass value="1.0"/>
      <inertia ixx="0.01" ixy="0" ixz="0" iyy="0.01" iyz="0" izz="0.01"/>
    </inertial>
    <visual>
      <material name="DarpaGrey"/>
      <origin rpy="0 0 0" xyz="0 0.05 0"/>
      <geometry>
        <mesh filename="package://apollo_robot_model/meshes/lbr0.stl"/>
      </geometry>
    </visual>
    <collision>
      <origin rpy="0 0 0" xyz="0 0.05 0"/>
      <geometry>
        <mesh filename="package://apollo_robot_model/meshes/collision/lbr0_smpl.stl"/>
      </geometry>
    </collision>
  </link>
  <joint name="L_SFE" type="revolute">
    <origin rpy="-1.57079632679 -0.0 0" xyz="0 0.1605 0"/>
    <parent link="L_COLLARBONE"/>
    <child link="L_SHOULDER"/>
    <axis xyz="0 0 -1.0"/>
    <dynamics damping="25"/>
    <limit effort="200" lower="-2.96" upper="2.96" velocity="1.9634"/>
  </joint>
  <link name="L_SHOULDER">
    <inertial>
      <origin rpy="0 0 0" xyz="0 0 0"/>
      <mass value="5.9907"/>
      <inertia ixx="0.01" ixy="0" ixz="0" iyy="0.01" iyz="0" izz="0.01"/>
    </inertial>
    <visual>
      <material name="DarpaGrey"/>
      <origin rpy="0 0 1.57079632679" xyz="0 0 0"/>
      <geometry>
        <mesh filename="package://apollo_robot_model/meshes/lbr1.stl"/>
      </geometry>
    </visual>
    <collision>
      <origin rpy="0 0 1.57079632679" xyz="0 0 0"/>
      <geometry>
        <mesh filename="package://apollo_robot_model/meshes/collision/lbr1_smpl.stl"/>
      </geometry>
    </collision>
  </link>
  <joint name="L_SAA" type="revolute">
    <origin rpy="1.57079632679 3.14149632679 1.57079632679" xyz="0 -0.002 0.1915"/>
    <parent link="L_SHOULDER"/>
    <child link="L_UPPER_ARM_IN_SHOULDER"/>
    <axis xyz="0 0 -1.0"/>
    <dynamics damping="25"/>
    <limit effort="200" lower="-3.1" upper="-0.1" velocity="1.9634"/>
  </joint>
  <link name="L_UPPER_ARM_IN_SHOULDER">
    <inertial>
      <origin rpy="0 0 0" xyz="0 0 0"/>
      <mass value="5.734939"/>
      <inertia ixx="0.03" ixy="0" ixz="0" iyy="0.03" iyz="0" izz="0.03"/>
    </inertial>
    <visual>
      <material name="DarpaGrey"/>
      <origin rpy="0 0 1.57079632679" xyz="0 0 0"/>
      <geometry>
        <mesh filename="package://apollo_robot_model/meshes/lbr2.stl"/>
      </geometry>
    </visual>
    <collision>
      <origin rpy="0 0 1.57079632679" xyz="0 0 0"/>
      <geometry>
        <mesh filename="package://apollo_robot_model/meshes/collision/lbr2_smpl.stl"/>
      </geometry>
    </collision>
  </link>
  <joint name="L_HR" type="revolute">
    <origin rpy="-1.57079632679  -0.523596326795 1.57079632679" xyz="-0.2085 0 0"/>
    <parent link="L_UPPER_ARM_IN_SHOULDER"/>
    <child link="L_UPPER_ARM"/>
    <axis xyz="0 0 -1.0"/>
    <dynamics damping="25"/>
    <limit effort="100" lower="-2.96" upper="2.96" velocity="1.9634"/>
  </joint>
  <link name="L_UPPER_ARM">
    <inertial>
      <origin rpy="0 0 0" xyz="0 0 0"/>
      <mass value="4.214668"/>
      <inertia ixx="0.03" ixy="0" ixz="0" iyy="0.03" iyz="0" izz="0.03"/>
    </inertial>
    <visual>
      <material name="DarpaGrey"/>
      <origin rpy="0 0 1.57079632679" xyz="0 0 0"/>
      <geometry>
        <mesh filename="package://apollo_robot_model/meshes/lbr3.stl"/>
      </geometry>
    </visual>
    <collision>
      <origin rpy="0 0 1.57079632679" xyz="0 0 0"/>
      <geometry>
        <mesh filename="package://apollo_robot_model/meshes/collision/lbr3_smpl.stl"/>
      </geometry>
    </collision>
  </link>
  <joint name="L_EB" type="revolute">
    <origin rpy="-1.57079632679 -1.57079632679 1.57079632679" xyz="0 0.002 0.1915"/>
    <parent link="L_UPPER_ARM"/>
    <child link="L_FOREARM"/>
    <axis xyz="0 0 -1.0"/>
    <dynamics damping="25"/>
    <limit effort="100" lower="-2.09" upper="2.09" velocity="1.9634"/>
  </joint>
  <link name="L_FOREARM">
    <inertial>
      <origin rpy="0 0 0" xyz="0 0 0"/>
      <mass value="3.669819"/>
      <inertia ixx="0.03" ixy="0" ixz="0" iyy="0.03" iyz="0" izz="0.03"/>
    </inertial>
    <visual>
      <material name="DarpaGrey"/>
      <origin rpy="0 0 1.57079632679" xyz="0 0 0"/>
      <geometry>
        <mesh filename="package://apollo_robot_model/meshes/lbr4.stl"/>
      </geometry>
    </visual>
    <collision>
      <origin rpy="0 0 1.57079632679" xyz="0 0 0"/>
      <geometry>
        <mesh filename="package://apollo_robot_model/meshes/collision/lbr4_smpl.stl"/>
      </geometry>
    </collision>
  </link>
  <joint name="L_WR" type="revolute">
    <origin rpy="1.57079632679 3.14149632679 1.57079632679" xyz="0.2085 0 0"/>
    <parent link="L_FOREARM"/>
    <child link="L_UPPER_WRIST_YAW"/>
    <axis xyz="0 0 -1.0"/>
    <dynamics damping="25"/>
    <limit effort="100" lower="-3.1" upper="1.35" velocity="3.1415926"/>
  </joint>
  <link name="L_UPPER_WRIST_YAW">
    <inertial>
      <origin rpy="0 0 0" xyz="0 0 0"/>
      <mass value="2.313272"/>
      <inertia ixx="0.03" ixy="0" ixz="0" iyy="0.03" iyz="0" izz="0.03"/>
    </inertial>
    <visual>
      <material name="DarpaGrey"/>
      <origin rpy="0 0 1.57079632679" xyz="0 0 0"/>
      <geometry>
        <mesh filename="package://apollo_robot_model/meshes/lbr5.stl"/>
      </geometry>
    </visual>
    <collision>
      <origin rpy="0 0 1.57079632679" xyz="0 0 0"/>
      <geometry>
        <mesh filename="package://apollo_robot_model/meshes/collision/lbr5_smpl.stl"/>
      </geometry>
    </collision>
  </link>
  <joint name="L_WFE" type="revolute">
    <origin rpy="1.5708 -0.0 1.57079632679" xyz="-0.046 0 0.1815"/>
    <parent link="L_UPPER_WRIST_YAW"/>
    <child link="L_UPPER_WRIST_PITCH"/>
    <axis xyz="0 0 -1.0"/>
    <dynamics damping="25"/>
    <limit effort="30" lower="-2.09" upper="2.09" velocity="1.9634"/>
  </joint>
  <link name="L_UPPER_WRIST_PITCH">
    <inertial>
      <origin rpy="0 0 0" xyz="0 0 0"/>
      <mass value="2.057856"/>
      <inertia ixx="0.01" ixy="0" ixz="0" iyy="0.01" iyz="0" izz="0.01"/>
    </inertial>
    <visual>
      <material name="DarpaGrey"/>
      <origin rpy="0 0 0" xyz="0 0 0"/>
      <geometry>
        <mesh filename="package://apollo_robot_model/meshes/lbr6.stl"/>
      </geometry>
    </visual>
    <collision>
      <origin rpy="0 0 0" xyz="0 0 0"/>
      <geometry>
        <mesh filename="package://apollo_robot_model/meshes/collision/lbr6_smpl.stl"/>
      </geometry>
    </collision>
  </link>
  <joint name="L_WAA" type="revolute">
    <origin rpy="-1.57079632679 -1.57079632679 0" xyz="0 0.057 0.0455"/>
    <parent link="L_UPPER_WRIST_PITCH"/>
    <child link="L_LOWER_WRIST"/>
    <axis xyz="0 0 -1.0"/>
    <dynamics damping="25"/>
    <limit effort="30" lower="-2.96" upper="2.96" velocity="1.9634"/>
  </joint>
  <link name="L_LOWER_WRIST">
    <inertial>
      <origin rpy="0 0 0" xyz="0 0 0"/>
      <mass value="1.120198"/>
      <inertia ixx="0.01" ixy="0" ixz="0" iyy="0.01" iyz="0" izz="0.01"/>
    </inertial>
    <visual>
      <material name="DarpaGrey"/>
      <origin rpy="0 0 0" xyz="0 0 0"/>
      <geometry>
        <mesh filename="package://apollo_robot_model/meshes/lbr7.stl"/>
      </geometry>
    </visual>
    <collision>
      <origin rpy="0 0 0" xyz="0 0 0"/>
      <geometry>
        <mesh filename="package://apollo_robot_model/meshes/collision/lbr7_smpl.stl"/>
      </geometry>
    </collision>
  </link>
  <joint name="L_Arm_PalmBlueComponentJoint" type="fixed">
    <parent link="L_LOWER_WRIST"/>
    <child link="L_ARM_PALM"/>
    <origin rpy="0 0 3.14159265359" xyz="0 0 0.03"/>
  </joint>
  <link name="L_ARM_PALM">
    <inertial>
      <origin xyz="0 0 0"/>
      <mass value="0.00000001"/>
      <inertia ixx="0.00000001" ixy="0.00000001" ixz="-0.00000001" iyy="0.00000001" iyz="-0.00000001" izz="0.00000001"/>
    </inertial>
    <visual>
      <material name="DarpaGrey"/>
      <material name="DarpaBlue"/>
      <origin rpy="1.57079632679 0 0" xyz="0 0 0"/>
      <geometry>
        <mesh filename="package://apollo_robot_model/meshes/wamLowerWristFTPalmLink7.stl"/>
      </geometry>
    </visual>
    <collision>
      <origin rpy="1.57079632679 0 0" xyz="0 0 0"/>
      <geometry>
        <mesh filename="package://apollo_robot_model/meshes/collision/wamLowerWristFTPalmLink7_smpl.stl"/>
      </geometry>
    </collision>
  </link>
  <link name="L_PALM"/>
  <link name="L_KUKA_TOOL"/>
  <link name="L_FORCE_TORQUE_SENSOR"/>
  <joint name="L_Arm_ForceTorqueJoint" type="fixed">
    <parent link="L_ARM_PALM"/>
    <child link="L_FORCE_TORQUE_SENSOR"/>
    <origin rpy="0 0 1.57079632679" xyz="0 0 0.0131834"/>
    <!-- 0.0131834 = .0059834 from wrist to f-t + .0072 from ft to sensor origin-->
  </joint>
  <joint name="L_Arm_PalmJoint" type="fixed">
    <parent link="L_ARM_PALM"/>
    <child link="L_PALM"/>
    <origin rpy="0 0 3.14159265359" xyz="0 0 0.1033"/>
  </joint>
  <joint name="L_Arm_ToolJoint" type="fixed">
    <parent link="L_ARM_PALM"/>
    <child link="L_KUKA_TOOL"/>
    <origin rpy="0 0 1.57079632679" xyz="0 0 0"/>
  </joint>
  <gazebo reference="L_0_link">
    <material value="PR2/Red"/>
    <turnGravityOff>false</turnGravityOff>
  </gazebo>
  <gazebo reference="L_1_link">
    <material value="PR2/Blue"/>
    <turnGravityOff>false</turnGravityOff>
  </gazebo>
  <gazebo reference="L_2_link">
    <material value="PR2/Red"/>
    <turnGravityOff>false</turnGravityOff>
  </gazebo>
  <gazebo reference="L_3_link">
    <material value="PR2/Blue"/>
    <turnGravityOff>false</turnGravityOff>
  </gazebo>
  <gazebo reference="L_4_link">
    <material value="PR2/Red"/>
    <turnGravityOff>false</turnGravityOff>
  </gazebo>
  <gazebo reference="L_5_link">
    <material value="PR2/Blue"/>
    <turnGravityOff>false</turnGravityOff>
  </gazebo>
  <gazebo reference="L_6_link">
    <material value="PR2/Red"/>
    <turnGravityOff>false</turnGravityOff>
  </gazebo>
  <gazebo reference="L_7_link">
    <material value="PR2/Blue"/>
    <turnGravityOff>false</turnGravityOff>
  </gazebo>
  <transmission name="L_1_trans" type="pr2_mechanism_model/SimpleTransmission">
    <actuator name="L_1_motor"/>
    <joint name="L_1_joint"/>
    <mechanicalReduction>1</mechanicalReduction>
  </transmission>
  <transmission name="L_2_trans" type="pr2_mechanism_model/SimpleTransmission">
    <actuator name="L_2_motor"/>
    <joint name="L_2_joint"/>
    <mechanicalReduction>1</mechanicalReduction>
  </transmission>
  <transmission name="L_3_trans" type="pr2_mechanism_model/SimpleTransmission">
    <actuator name="L_3_motor"/>
    <joint name="L_3_joint"/>
    <mechanicalReduction>1</mechanicalReduction>
  </transmission>
  <transmission name="L_4_trans" type="pr2_mechanism_model/SimpleTransmission">
    <actuator name="L_4_motor"/>
    <joint name="L_4_joint"/>
    <mechanicalReduction>1</mechanicalReduction>
  </transmission>
  <transmission name="L_5_trans" type="pr2_mechanism_model/SimpleTransmission">
    <actuator name="L_5_motor"/>
    <joint name="L_5_joint"/>
    <mechanicalReduction>1</mechanicalReduction>
  </transmission>
  <transmission name="L_6_trans" type="pr2_mechanism_model/SimpleTransmission">
    <actuator name="L_6_motor"/>
    <joint name="L_6_joint"/>
    <mechanicalReduction>1</mechanicalReduction>
  </transmission>
  <transmission name="L_7_trans" type="pr2_mechanism_model/SimpleTransmission">
    <actuator name="L_7_motor"/>
    <joint name="L_7_joint"/>
    <mechanicalReduction>1</mechanicalReduction>
  </transmission>
  <link name="L_HAND_M_FINGER_KNUCKLE_2">
    <visual>
      <material name="DarpaGrey"/>
      <origin rpy="3.14159265359 1.57079632679 0" xyz="0 0 0"/>
      <geometry>
        <mesh filename="package://apollo_robot_model/meshes/secondFingerLink.stl"/>
      </geometry>
    </visual>
    <inertial>
      <origin xyz=".031720 .001070 -.000586"/>
      <mass value="0.057957"/>
      <inertia ixx="0.00000461" ixy="0.00000003" ixz="0.00000164" iyy="0.00003590" iyz="0.00000004" izz="0.00003682"/>
    </inertial>
    <collision>
      <origin rpy="3.14159265359 1.57079632679 0" xyz="0 0 0"/>
      <geometry>
        <mesh filename="package://apollo_robot_model/meshes/collision/secondFingerLink_smpl.stl"/>
      </geometry>
      <mu1 value="50000.0"/>
      <mu2 value="50000.0"/>
      <kp value="1000000.0"/>
      <kd value="1.0"/>
    </collision>
  </link>
  <gazebo reference="L_HAND_M_FINGER_KNUCKLE_2">
    <material>
                PR2/Grey2
            </material>
    <turnGravityOff>
                true
            </turnGravityOff>
    <selfCollide>
                true
            </selfCollide>
  </gazebo>
  <transmission name="DarmSim_LArm_BHand_FingerMKnuckleTwo_trans" type="pr2_mechanism_model/SimpleTransmission">
    <actuator name="DarmSim_LArm_BHand_FingerMKnuckleTwo_motor"/>
    <joint name="L_Arm_M_Finger_KnuckleTwoJoint"/>
    <mechanicalReduction>1</mechanicalReduction>
    <motorTorqueConstant>1</motorTorqueConstant>
    <pulsesPerRevolution>90000</pulsesPerRevolution>
  </transmission>
  <link name="L_HAND_M_FINGER_KNUCKLE_3">
    <visual>
      <material name="DarpaGrey"/>
      <origin rpy="0 1.57079632679 0" xyz="0 0 0"/>
      <geometry>
        <mesh filename="package://apollo_robot_model/meshes/thirdFingerLink.stl"/>
      </geometry>
    </visual>
    <inertial>
      <origin xyz="0.01970974 0.00182016 0.00020041"/>
      <mass value="0.03421781"/>
      <inertia ixx="0.00000287" ixy="0.00000091" ixz="-0.00000007" iyy="0.00001329" iyz="-0.00000002" izz="0.00001214"/>
    </inertial>
    <collision>
      <origin rpy="0 1.57079632679 0" xyz="0 0 0"/>
      <geometry>
        <mesh filename="package://apollo_robot_model/meshes/collision/thirdFingerLink_smpl.stl"/>
      </geometry>
      <mu1 value="50000.0"/>
      <mu2 value="50000.0"/>
      <kp value="1000000.0"/>
      <kd value="1.0"/>
    </collision>
  </link>
  <gazebo reference="L_HAND_M_FINGER_KNUCKLE_3">
    <material>
                PR2/Grey2
            </material>
    <turnGravityOff>
                true
            </turnGravityOff>
    <selfCollide>
                true
            </selfCollide>
  </gazebo>
  <transmission name="DarmSim_LArm_BHand_FingerMKnuckleThree_trans" type="pr2_mechanism_model/SimpleTransmission">
    <actuator name="DarmSim_LArm_BHand_FingerMKnuckleThree_motor"/>
    <joint name="L_Arm_M_Finger_KnuckleThreeJoint"/>
    <mechanicalReduction>1</mechanicalReduction>
    <motorTorqueConstant>1</motorTorqueConstant>
    <pulsesPerRevolution>90000</pulsesPerRevolution>
  </transmission>
  <link name="L_HAND_M_FINGER_TIP"/>
  <joint name="L_MF" type="revolute">
    <parent link="L_ARM_PALM"/>
    <child link="L_HAND_M_FINGER_KNUCKLE_2"/>
    <origin rpy="-1.57079632679 -0.0429350996 -1.57079632679" xyz="0 -0.05 0.09938"/>
    <axis xyz="0 0 -1"/>
    <limit effort="1" lower="0" upper="2.44" velocity="3.27"/>
    <dynamics damping="0.005" friction="100.0"/>
  </joint>
  <joint name="L_MF2" type="revolute">
    <parent link="L_HAND_M_FINGER_KNUCKLE_2"/>
    <child link="L_HAND_M_FINGER_KNUCKLE_3"/>
    <origin rpy="0 0 0" xyz="0.07 0 0"/>
    <!--<origin xyz="0.07 0 0" rpy="0 0 -0.733038286"/>-->
    <axis xyz="0 0 -1"/>
    <limit effort="1" lower="0.698131700798" upper="1.57079632679" velocity="3.27"/>
    <dynamics damping="0.005" friction="100.0"/>
    <!--<mimic joint="${side}_${number}F" multiplier="1" offset="0"/>-->
  </joint>
  <joint name="L_MF3" type="fixed">
    <parent link="L_HAND_M_FINGER_KNUCKLE_3"/>
    <child link="L_HAND_M_FINGER_TIP"/>
    <origin rpy="0 0 0" xyz="0.056 0 0"/>
  </joint>
  <link name="L_HAND_L_FINGER_KNUCKLE_1">
    <visual>
      <material name="DarpaGrey"/>
      <origin rpy="1.57079632679 0 -1.57079632679" xyz="0 0 0"/>
      <geometry>
        <mesh filename="package://apollo_robot_model/meshes/firstFingerLink.stl"/>
      </geometry>
      <mu1 value="50000.0"/>
      <mu2 value="50000.0"/>
      <kp value="1000000.0"/>
      <kd value="1.0"/>
    </visual>
    <inertial>
      <origin xyz="0.03201666 -0.00086502 0.00890075"/>
      <mass value="0.16252678"/>
      <inertia ixx="0.00002567" ixy="-0.00000146" ixz="0.00001128" iyy="0.00008818" iyz="-0.00000094" izz="0.00007827"/>
    </inertial>
    <collision>
      <origin rpy="1.57079632679 0 -1.57079632679" xyz="0 0 0"/>
      <geometry>
        <mesh filename="package://apollo_robot_model/meshes/collision/firstFingerLink_smpl.stl"/>
      </geometry>
    </collision>
  </link>
  <gazebo reference="L_HAND_L_FINGER_KNUCKLE_1">
    <material>
                PR2/Grey2
            </material>
    <turnGravityOff>
                true
            </turnGravityOff>
    <selfCollide>
                true
            </selfCollide>
  </gazebo>
  <transmission name="DarmSim_LArm_BHand_FingerOneKnuckleOne_trans" type="pr2_mechanism_model/SimpleTransmission">
    <actuator name="DarmSim_LArm_BHand_FingerOneKnuckleOne_motor"/>
    <joint name="L_Arm_FingerOne_KnuckleOneJoint"/>
    <mechanicalReduction>1</mechanicalReduction>
    <motorTorqueConstant>1</motorTorqueConstant>
    <pulsesPerRevolution>90000</pulsesPerRevolution>
  </transmission>
  <link name="L_HAND_L_FINGER_KNUCKLE_2">
    <visual>
      <material name="DarpaGrey"/>
      <origin rpy="3.14159265359 1.57079632679 0" xyz="0 0 0"/>
      <geometry>
        <mesh filename="package://apollo_robot_model/meshes/secondFingerLink.stl"/>
      </geometry>
    </visual>
    <inertial>
      <origin xyz=".031720 .001070 -.000586"/>
      <mass value="0.057957"/>
      <inertia ixx="0.00000461" ixy="0.00000003" ixz="0.00000164" iyy="0.00003590" iyz="0.00000004" izz="0.00003682"/>
    </inertial>
    <collision>
      <origin rpy="3.14159265359 1.57079632679 0" xyz="0 0 0"/>
      <geometry>
        <mesh filename="package://apollo_robot_model/meshes/collision/secondFingerLink_smpl.stl"/>
      </geometry>
      <mu1 value="50000.0"/>
      <mu2 value="50000.0"/>
      <kp value="1000000.0"/>
      <kd value="1.0"/>
    </collision>
  </link>
  <gazebo reference="L_HAND_L_FINGER_KNUCKLE_2">
    <material>
                PR2/Grey2
            </material>
    <turnGravityOff>
                true
            </turnGravityOff>
    <selfCollide>
                true
            </selfCollide>
  </gazebo>
  <transmission name="DarmSim_LArm_BHand_FingerLKnuckleTwo_trans" type="pr2_mechanism_model/SimpleTransmission">
    <actuator name="DarmSim_LArm_BHand_FingerLKnuckleTwo_motor"/>
    <joint name="L_Arm_L_Finger_KnuckleTwoJoint"/>
    <mechanicalReduction>1</mechanicalReduction>
    <motorTorqueConstant>1</motorTorqueConstant>
    <pulsesPerRevolution>90000</pulsesPerRevolution>
  </transmission>
  <link name="L_HAND_L_FINGER_KNUCKLE_3">
    <visual>
      <material name="DarpaGrey"/>
      <origin rpy="0 1.57079632679 0" xyz="0 0 0"/>
      <geometry>
        <mesh filename="package://apollo_robot_model/meshes/thirdFingerLink.stl"/>
      </geometry>
    </visual>
    <inertial>
      <origin xyz="0.01970974 0.00182016 0.00020041"/>
      <mass value="0.03421781"/>
      <inertia ixx="0.00000287" ixy="0.00000091" ixz="-0.00000007" iyy="0.00001329" iyz="-0.00000002" izz="0.00001214"/>
    </inertial>
    <collision>
      <origin rpy="0 1.57079632679 0" xyz="0 0 0"/>
      <geometry>
        <mesh filename="package://apollo_robot_model/meshes/collision/thirdFingerLink_smpl.stl"/>
      </geometry>
      <mu1 value="50000.0"/>
      <mu2 value="50000.0"/>
      <kp value="1000000.0"/>
      <kd value="1.0"/>
    </collision>
  </link>
  <gazebo reference="L_HAND_L_FINGER_KNUCKLE_3">
    <material>
                PR2/Grey2
            </material>
    <turnGravityOff>
                true
            </turnGravityOff>
    <selfCollide>
                true
            </selfCollide>
  </gazebo>
  <transmission name="DarmSim_LArm_BHand_FingerLKnuckleThree_trans" type="pr2_mechanism_model/SimpleTransmission">
    <actuator name="DarmSim_LArm_BHand_FingerLKnuckleThree_motor"/>
    <joint name="L_Arm_L_Finger_KnuckleThreeJoint"/>
    <mechanicalReduction>1</mechanicalReduction>
    <motorTorqueConstant>1</motorTorqueConstant>
    <pulsesPerRevolution>90000</pulsesPerRevolution>
  </transmission>
  <link name="L_HAND_L_FINGER_TIP"/>
  <joint name="L_LF" type="revolute">
    <parent link="L_HAND_L_FINGER_KNUCKLE_1"/>
    <child link="L_HAND_L_FINGER_KNUCKLE_2"/>
    <origin rpy="-1.57079632679 -0.0429350996 0" xyz=".05 0 0.02140"/>
    <axis xyz="0 0 -1"/>
    <limit effort="1" lower="0" upper="2.44" velocity="3.27"/>
    <dynamics damping="0.005" friction="100.0"/>
  </joint>
  <joint name="L_LF2" type="revolute">
    <parent link="L_HAND_L_FINGER_KNUCKLE_2"/>
    <child link="L_HAND_L_FINGER_KNUCKLE_3"/>
    <origin rpy="0 0 0" xyz="0.07 0 0"/>
    <!--<origin xyz="0.07 0 0" rpy="0 0 -0.733038286"/>-->
    <axis xyz="0 0 -1"/>
    <limit effort="1" lower="0.698131700798" upper="1.57079632679" velocity="3.27"/>
    <dynamics damping="0.005" friction="100.0"/>
    <!--<mimic joint="${side}_${number}F" multiplier="1" offset="0"/>-->
  </joint>
  <joint name="L_LF3" type="fixed">
    <parent link="L_HAND_L_FINGER_KNUCKLE_3"/>
    <child link="L_HAND_L_FINGER_TIP"/>
    <origin rpy="0 0 0" xyz="0.056 0 0"/>
  </joint>
  <link name="L_HAND_R_FINGER_KNUCKLE_1">
    <visual>
      <material name="DarpaGrey"/>
      <origin rpy="1.57079632679 0 -1.57079632679" xyz="0 0 0"/>
      <geometry>
        <mesh filename="package://apollo_robot_model/meshes/firstFingerLink.stl"/>
      </geometry>
    </visual>
    <inertial>
      <origin xyz="0.03201666 -0.00086502 0.00890075"/>
      <mass value="0.16252678"/>
      <inertia ixx="0.00002567" ixy="-0.00000146" ixz="0.00001128" iyy="0.00008818" iyz="-0.00000094" izz="0.00007827"/>
    </inertial>
    <collision>
      <origin rpy="1.57079632679 0 -1.57079632679" xyz="0 0 0"/>
      <geometry>
        <mesh filename="package://apollo_robot_model/meshes/collision/firstFingerLink_smpl.stl"/>
      </geometry>
    </collision>
  </link>
  <gazebo reference="L_HAND_R_FINGER_KNUCKLE_1">
    <material>
                PR2/Grey2
            </material>
    <turnGravityOff>
                true
            </turnGravityOff>
    <selfCollide>
                true
            </selfCollide>
  </gazebo>
  <transmission name="DarmSim_LArm_BHand_FingerTwoKnuckleOne_trans" type="pr2_mechanism_model/SimpleTransmission">
    <actuator name="DarmSim_LArm_BHand_FingerTwoKnuckleOne_motor"/>
    <joint name="L_Arm_FingerTwo_KnuckleOneJoint"/>
    <mechanicalReduction>1</mechanicalReduction>
    <motorTorqueConstant>1</motorTorqueConstant>
    <pulsesPerRevolution>90000</pulsesPerRevolution>
  </transmission>
  <link name="L_HAND_R_FINGER_KNUCKLE_2">
    <visual>
      <material name="DarpaGrey"/>
      <origin rpy="3.14159265359 1.57079632679 0" xyz="0 0 0"/>
      <geometry>
        <mesh filename="package://apollo_robot_model/meshes/secondFingerLink.stl"/>
      </geometry>
    </visual>
    <inertial>
      <origin xyz=".031720 .001070 -.000586"/>
      <mass value="0.057957"/>
      <inertia ixx="0.00000461" ixy="0.00000003" ixz="0.00000164" iyy="0.00003590" iyz="0.00000004" izz="0.00003682"/>
    </inertial>
    <collision>
      <origin rpy="3.14159265359 1.57079632679 0" xyz="0 0 0"/>
      <geometry>
        <mesh filename="package://apollo_robot_model/meshes/collision/secondFingerLink_smpl.stl"/>
      </geometry>
      <mu1 value="50000.0"/>
      <mu2 value="50000.0"/>
      <kp value="1000000.0"/>
      <kd value="1.0"/>
    </collision>
  </link>
  <gazebo reference="L_HAND_R_FINGER_KNUCKLE_2">
    <material>
                PR2/Grey2
            </material>
    <turnGravityOff>
                true
            </turnGravityOff>
    <selfCollide>
                true
            </selfCollide>
  </gazebo>
  <transmission name="DarmSim_LArm_BHand_FingerRKnuckleTwo_trans" type="pr2_mechanism_model/SimpleTransmission">
    <actuator name="DarmSim_LArm_BHand_FingerRKnuckleTwo_motor"/>
    <joint name="L_Arm_R_Finger_KnuckleTwoJoint"/>
    <mechanicalReduction>1</mechanicalReduction>
    <motorTorqueConstant>1</motorTorqueConstant>
    <pulsesPerRevolution>90000</pulsesPerRevolution>
  </transmission>
  <link name="L_HAND_R_FINGER_KNUCKLE_3">
    <visual>
      <material name="DarpaGrey"/>
      <origin rpy="0 1.57079632679 0" xyz="0 0 0"/>
      <geometry>
        <mesh filename="package://apollo_robot_model/meshes/thirdFingerLink.stl"/>
      </geometry>
    </visual>
    <inertial>
      <origin xyz="0.01970974 0.00182016 0.00020041"/>
      <mass value="0.03421781"/>
      <inertia ixx="0.00000287" ixy="0.00000091" ixz="-0.00000007" iyy="0.00001329" iyz="-0.00000002" izz="0.00001214"/>
    </inertial>
    <collision>
      <origin rpy="0 1.57079632679 0" xyz="0 0 0"/>
      <geometry>
        <mesh filename="package://apollo_robot_model/meshes/collision/thirdFingerLink_smpl.stl"/>
      </geometry>
      <mu1 value="50000.0"/>
      <mu2 value="50000.0"/>
      <kp value="1000000.0"/>
      <kd value="1.0"/>
    </collision>
  </link>
  <gazebo reference="L_HAND_R_FINGER_KNUCKLE_3">
    <material>
                PR2/Grey2
            </material>
    <turnGravityOff>
                true
            </turnGravityOff>
    <selfCollide>
                true
            </selfCollide>
  </gazebo>
  <transmission name="DarmSim_LArm_BHand_FingerRKnuckleThree_trans" type="pr2_mechanism_model/SimpleTransmission">
    <actuator name="DarmSim_LArm_BHand_FingerRKnuckleThree_motor"/>
    <joint name="L_Arm_R_Finger_KnuckleThreeJoint"/>
    <mechanicalReduction>1</mechanicalReduction>
    <motorTorqueConstant>1</motorTorqueConstant>
    <pulsesPerRevolution>90000</pulsesPerRevolution>
  </transmission>
  <link name="L_HAND_R_FINGER_TIP"/>
  <joint name="L_RF" type="revolute">
    <parent link="L_HAND_R_FINGER_KNUCKLE_1"/>
    <child link="L_HAND_R_FINGER_KNUCKLE_2"/>
    <origin rpy="-1.57079632679 -0.0429350996 0" xyz=".05 0 0.02140"/>
    <axis xyz="0 0 -1"/>
    <limit effort="1" lower="0" upper="2.44" velocity="3.27"/>
    <dynamics damping="0.005" friction="100.0"/>
  </joint>
  <joint name="L_RF2" type="revolute">
    <parent link="L_HAND_R_FINGER_KNUCKLE_2"/>
    <child link="L_HAND_R_FINGER_KNUCKLE_3"/>
    <origin rpy="0 0 0" xyz="0.07 0 0"/>
    <!--<origin xyz="0.07 0 0" rpy="0 0 -0.733038286"/>-->
    <axis xyz="0 0 -1"/>
    <limit effort="1" lower="0.698131700798" upper="1.57079632679" velocity="3.27"/>
    <dynamics damping="0.005" friction="100.0"/>
    <!--<mimic joint="${side}_${number}F" multiplier="1" offset="0"/>-->
  </joint>
  <joint name="L_RF3" type="fixed">
    <parent link="L_HAND_R_FINGER_KNUCKLE_3"/>
    <child link="L_HAND_R_FINGER_TIP"/>
    <origin rpy="0 0 0" xyz="0.056 0 0"/>
  </joint>
  <joint name="L_FR" type="revolute">
    <parent link="L_ARM_PALM"/>
    <child link="L_HAND_L_FINGER_KNUCKLE_1"/>
    <origin rpy="0 0 1.57079632679" xyz=".02497 0 0.07798"/>
    <axis xyz="0 0 -1"/>
    <limit effort="1" lower="0" upper="3.14159265359" velocity="3.27"/>
    <dynamics damping="0.005" friction="100.0"/>
  </joint>
  <joint name="L_FR2" type="revolute">
    <parent link="L_ARM_PALM"/>
    <child link="L_HAND_R_FINGER_KNUCKLE_1"/>
    <origin rpy="0 0 1.57079632679" xyz="-.02497 0 0.07798"/>
    <axis xyz="0 0 1"/>
    <limit effort="1" lower="0" upper="3.14159265359" velocity="3.27"/>
    <dynamics damping="0.005" friction="100.0"/>
    <mimic joint="L_FR" multiplier="1" offset="0"/>
  </joint>
  <joint name="R_BASE" type="fixed">
    <origin rpy="0 3.14159265359 -1.0471975512" xyz="0 0 0"/>
    <parent link="BASE"/>
    <child link="R_COLLARBONE"/>
  </joint>
  <link name="R_COLLARBONE">
    <inertial>
      <origin rpy="0 0 0" xyz="0 0 0"/>
      <mass value="1.0"/>
      <inertia ixx="0.01" ixy="0" ixz="0" iyy="0.01" iyz="0" izz="0.01"/>
    </inertial>
    <visual>
      <material name="DarpaGrey"/>
      <origin rpy="0 0 0" xyz="0 0.05 0"/>
      <geometry>
        <mesh filename="package://apollo_robot_model/meshes/lbr0.stl"/>
      </geometry>
    </visual>
    <collision>
      <origin rpy="0 0 0" xyz="0 0.05 0"/>
      <geometry>
        <mesh filename="package://apollo_robot_model/meshes/collision/lbr0_smpl.stl"/>
      </geometry>
    </collision>
  </link>
  <joint name="R_SFE" type="revolute">
    <origin rpy="-1.57079632679 0.0 0" xyz="0 0.1605 0"/>
    <parent link="R_COLLARBONE"/>
    <child link="R_SHOULDER"/>
    <axis xyz="0 0 1.0"/>
    <dynamics damping="25"/>
    <limit effort="200" lower="-2.96" upper="2.96" velocity="1.9634"/>
  </joint>
  <link name="R_SHOULDER">
    <inertial>
      <origin rpy="0 0 0" xyz="0 0 0"/>
      <mass value="5.9907"/>
      <inertia ixx="0.01" ixy="0" ixz="0" iyy="0.01" iyz="0" izz="0.01"/>
    </inertial>
    <visual>
      <material name="DarpaGrey"/>
      <origin rpy="0 0 1.57079632679" xyz="0 0 0"/>
      <geometry>
        <mesh filename="package://apollo_robot_model/meshes/lbr1.stl"/>
      </geometry>
    </visual>
    <collision>
      <origin rpy="0 0 1.57079632679" xyz="0 0 0"/>
      <geometry>
        <mesh filename="package://apollo_robot_model/meshes/collision/lbr1_smpl.stl"/>
      </geometry>
    </collision>
  </link>
  <joint name="R_SAA" type="revolute">
    <origin rpy="1.57079632679 9.63267948966e-05 1.57079632679" xyz="0 -0.002 0.1915"/>
    <parent link="R_SHOULDER"/>
    <child link="R_UPPER_ARM_IN_SHOULDER"/>
    <axis xyz="0 0 1.0"/>
    <dynamics damping="25"/>
    <limit effort="200" lower="-3.1" upper="-0.1" velocity="1.9634"/>
  </joint>
  <link name="R_UPPER_ARM_IN_SHOULDER">
    <inertial>
      <origin rpy="0 0 0" xyz="0 0 0"/>
      <mass value="5.734939"/>
      <inertia ixx="0.03" ixy="0" ixz="0" iyy="0.03" iyz="0" izz="0.03"/>
    </inertial>
    <visual>
      <material name="DarpaGrey"/>
      <origin rpy="0 0 1.57079632679" xyz="0 0 0"/>
      <geometry>
        <mesh filename="package://apollo_robot_model/meshes/lbr2.stl"/>
      </geometry>
    </visual>
    <collision>
      <origin rpy="0 0 1.57079632679" xyz="0 0 0"/>
      <geometry>
        <mesh filename="package://apollo_robot_model/meshes/collision/lbr2_smpl.stl"/>
      </geometry>
    </collision>
  </link>
  <joint name="R_HR" type="revolute">
    <origin rpy="-1.57079632679  -2.61799632679 1.57079632679" xyz="-0.2085 0 0"/>
    <parent link="R_UPPER_ARM_IN_SHOULDER"/>
    <child link="R_UPPER_ARM"/>
    <axis xyz="0 0 1.0"/>
    <dynamics damping="25"/>
    <limit effort="100" lower="-2.96" upper="2.96" velocity="1.9634"/>
  </joint>
  <link name="R_UPPER_ARM">
    <inertial>
      <origin rpy="0 0 0" xyz="0 0 0"/>
      <mass value="4.214668"/>
      <inertia ixx="0.03" ixy="0" ixz="0" iyy="0.03" iyz="0" izz="0.03"/>
    </inertial>
    <visual>
      <material name="DarpaGrey"/>
      <origin rpy="0 0 1.57079632679" xyz="0 0 0"/>
      <geometry>
        <mesh filename="package://apollo_robot_model/meshes/lbr3.stl"/>
      </geometry>
    </visual>
    <collision>
      <origin rpy="0 0 1.57079632679" xyz="0 0 0"/>
      <geometry>
        <mesh filename="package://apollo_robot_model/meshes/collision/lbr3_smpl.stl"/>
      </geometry>
    </collision>
  </link>
  <joint name="R_EB" type="revolute">
    <origin rpy="-1.57079632679 -1.57079632679 1.57079632679" xyz="0 0.002 0.1915"/>
    <parent link="R_UPPER_ARM"/>
    <child link="R_FOREARM"/>
    <axis xyz="0 0 1.0"/>
    <dynamics damping="25"/>
    <limit effort="100" lower="-2.09" upper="2.09" velocity="1.9634"/>
  </joint>
  <link name="R_FOREARM">
    <inertial>
      <origin rpy="0 0 0" xyz="0 0 0"/>
      <mass value="3.669819"/>
      <inertia ixx="0.03" ixy="0" ixz="0" iyy="0.03" iyz="0" izz="0.03"/>
    </inertial>
    <visual>
      <material name="DarpaGrey"/>
      <origin rpy="0 0 1.57079632679" xyz="0 0 0"/>
      <geometry>
        <mesh filename="package://apollo_robot_model/meshes/lbr4.stl"/>
      </geometry>
    </visual>
    <collision>
      <origin rpy="0 0 1.57079632679" xyz="0 0 0"/>
      <geometry>
        <mesh filename="package://apollo_robot_model/meshes/collision/lbr4_smpl.stl"/>
      </geometry>
    </collision>
  </link>
  <joint name="R_WR" type="revolute">
    <origin rpy="1.57079632679 9.63267948966e-05 1.57079632679" xyz="0.2085 0 0"/>
    <parent link="R_FOREARM"/>
    <child link="R_UPPER_WRIST_YAW"/>
    <axis xyz="0 0 1.0"/>
    <dynamics damping="25"/>
    <limit effort="100" lower="-3.1" upper="1.35" velocity="3.1415926"/>
  </joint>
  <link name="R_UPPER_WRIST_YAW">
    <inertial>
      <origin rpy="0 0 0" xyz="0 0 0"/>
      <mass value="2.313272"/>
      <inertia ixx="0.03" ixy="0" ixz="0" iyy="0.03" iyz="0" izz="0.03"/>
    </inertial>
    <visual>
      <material name="DarpaGrey"/>
      <origin rpy="0 0 1.57079632679" xyz="0 0 0"/>
      <geometry>
        <mesh filename="package://apollo_robot_model/meshes/lbr5.stl"/>
      </geometry>
    </visual>
    <collision>
      <origin rpy="0 0 1.57079632679" xyz="0 0 0"/>
      <geometry>
        <mesh filename="package://apollo_robot_model/meshes/collision/lbr5_smpl.stl"/>
      </geometry>
    </collision>
  </link>
  <joint name="R_WFE" type="revolute">
    <origin rpy="1.5708 0.0 1.57079632679" xyz="-0.046 0 0.1815"/>
    <parent link="R_UPPER_WRIST_YAW"/>
    <child link="R_UPPER_WRIST_PITCH"/>
    <axis xyz="0 0 1.0"/>
    <dynamics damping="25"/>
    <limit effort="30" lower="-2.09" upper="2.09" velocity="1.9634"/>
  </joint>
  <link name="R_UPPER_WRIST_PITCH">
    <inertial>
      <origin rpy="0 0 0" xyz="0 0 0"/>
      <mass value="2.057856"/>
      <inertia ixx="0.01" ixy="0" ixz="0" iyy="0.01" iyz="0" izz="0.01"/>
    </inertial>
    <visual>
      <material name="DarpaGrey"/>
      <origin rpy="0 0 0" xyz="0 0 0"/>
      <geometry>
        <mesh filename="package://apollo_robot_model/meshes/lbr6.stl"/>
      </geometry>
    </visual>
    <collision>
      <origin rpy="0 0 0" xyz="0 0 0"/>
      <geometry>
        <mesh filename="package://apollo_robot_model/meshes/collision/lbr6_smpl.stl"/>
      </geometry>
    </collision>
  </link>
  <joint name="R_WAA" type="revolute">
    <origin rpy="-1.57079632679 1.57079632679 0" xyz="0 0.057 0.0455"/>
    <parent link="R_UPPER_WRIST_PITCH"/>
    <child link="R_LOWER_WRIST"/>
    <axis xyz="0 0 1.0"/>
    <dynamics damping="25"/>
    <limit effort="30" lower="-2.96" upper="2.96" velocity="1.9634"/>
  </joint>
  <link name="R_LOWER_WRIST">
    <inertial>
      <origin rpy="0 0 0" xyz="0 0 0"/>
      <mass value="1.120198"/>
      <inertia ixx="0.01" ixy="0" ixz="0" iyy="0.01" iyz="0" izz="0.01"/>
    </inertial>
    <visual>
      <material name="DarpaGrey"/>
      <origin rpy="0 0 0" xyz="0 0 0"/>
      <geometry>
        <mesh filename="package://apollo_robot_model/meshes/lbr7.stl"/>
      </geometry>
    </visual>
    <collision>
      <origin rpy="0 0 0" xyz="0 0 0"/>
      <geometry>
        <mesh filename="package://apollo_robot_model/meshes/collision/lbr7_smpl.stl"/>
      </geometry>
    </collision>
  </link>
  <joint name="R_Arm_PalmBlueComponentJoint" type="fixed">
    <parent link="R_LOWER_WRIST"/>
    <child link="R_ARM_PALM"/>
    <origin rpy="0 0 3.14159265359" xyz="0 0 0.03"/>
  </joint>
  <link name="R_ARM_PALM">
    <inertial>
      <origin xyz="0 0 0"/>
      <mass value="0.00000001"/>
      <inertia ixx="0.00000001" ixy="0.00000001" ixz="-0.00000001" iyy="0.00000001" iyz="-0.00000001" izz="0.00000001"/>
    </inertial>
    <visual>
      <material name="DarpaGrey"/>
      <material name="DarpaBlue"/>
      <origin rpy="1.57079632679 0 0" xyz="0 0 0"/>
      <geometry>
        <mesh filename="package://apollo_robot_model/meshes/wamLowerWristFTPalmLink7.stl"/>
      </geometry>
    </visual>
    <collision>
      <origin rpy="1.57079632679 0 0" xyz="0 0 0"/>
      <geometry>
        <mesh filename="package://apollo_robot_model/meshes/collision/wamLowerWristFTPalmLink7_smpl.stl"/>
      </geometry>
    </collision>
  </link>
  <link name="R_PALM"/>
  <link name="R_KUKA_TOOL"/>
  <link name="R_FORCE_TORQUE_SENSOR"/>
  <joint name="R_Arm_ForceTorqueJoint" type="fixed">
    <parent link="R_ARM_PALM"/>
    <child link="R_FORCE_TORQUE_SENSOR"/>
    <origin rpy="0 0 1.57079632679" xyz="0 0 0.0131834"/>
    <!-- 0.0131834 = .0059834 from wrist to f-t + .0072 from ft to sensor origin-->
  </joint>
  <joint name="R_Arm_PalmJoint" type="fixed">
    <parent link="R_ARM_PALM"/>
    <child link="R_PALM"/>
    <origin rpy="0 0 3.14159265359" xyz="0 0 0.1033"/>
  </joint>
  <joint name="R_Arm_ToolJoint" type="fixed">
    <parent link="R_ARM_PALM"/>
    <child link="R_KUKA_TOOL"/>
    <origin rpy="0 0 1.57079632679" xyz="0 0 0"/>
  </joint>
  <gazebo reference="R_0_link">
    <material value="PR2/Red"/>
    <turnGravityOff>false</turnGravityOff>
  </gazebo>
  <gazebo reference="R_1_link">
    <material value="PR2/Blue"/>
    <turnGravityOff>false</turnGravityOff>
  </gazebo>
  <gazebo reference="R_2_link">
    <material value="PR2/Red"/>
    <turnGravityOff>false</turnGravityOff>
  </gazebo>
  <gazebo reference="R_3_link">
    <material value="PR2/Blue"/>
    <turnGravityOff>false</turnGravityOff>
  </gazebo>
  <gazebo reference="R_4_link">
    <material value="PR2/Red"/>
    <turnGravityOff>false</turnGravityOff>
  </gazebo>
  <gazebo reference="R_5_link">
    <material value="PR2/Blue"/>
    <turnGravityOff>false</turnGravityOff>
  </gazebo>
  <gazebo reference="R_6_link">
    <material value="PR2/Red"/>
    <turnGravityOff>false</turnGravityOff>
  </gazebo>
  <gazebo reference="R_7_link">
    <material value="PR2/Blue"/>
    <turnGravityOff>false</turnGravityOff>
  </gazebo>
  <transmission name="R_1_trans" type="pr2_mechanism_model/SimpleTransmission">
    <actuator name="R_1_motor"/>
    <joint name="R_1_joint"/>
    <mechanicalReduction>1</mechanicalReduction>
  </transmission>
  <transmission name="R_2_trans" type="pr2_mechanism_model/SimpleTransmission">
    <actuator name="R_2_motor"/>
    <joint name="R_2_joint"/>
    <mechanicalReduction>1</mechanicalReduction>
  </transmission>
  <transmission name="R_3_trans" type="pr2_mechanism_model/SimpleTransmission">
    <actuator name="R_3_motor"/>
    <joint name="R_3_joint"/>
    <mechanicalReduction>1</mechanicalReduction>
  </transmission>
  <transmission name="R_4_trans" type="pr2_mechanism_model/SimpleTransmission">
    <actuator name="R_4_motor"/>
    <joint name="R_4_joint"/>
    <mechanicalReduction>1</mechanicalReduction>
  </transmission>
  <transmission name="R_5_trans" type="pr2_mechanism_model/SimpleTransmission">
    <actuator name="R_5_motor"/>
    <joint name="R_5_joint"/>
    <mechanicalReduction>1</mechanicalReduction>
  </transmission>
  <transmission name="R_6_trans" type="pr2_mechanism_model/SimpleTransmission">
    <actuator name="R_6_motor"/>
    <joint name="R_6_joint"/>
    <mechanicalReduction>1</mechanicalReduction>
  </transmission>
  <transmission name="R_7_trans" type="pr2_mechanism_model/SimpleTransmission">
    <actuator name="R_7_motor"/>
    <joint name="R_7_joint"/>
    <mechanicalReduction>1</mechanicalReduction>
  </transmission>
  <link name="R_HAND_M_FINGER_KNUCKLE_2">
    <visual>
      <material name="DarpaGrey"/>
      <origin rpy="3.14159265359 1.57079632679 0" xyz="0 0 0"/>
      <geometry>
        <mesh filename="package://apollo_robot_model/meshes/secondFingerLink.stl"/>
      </geometry>
    </visual>
    <inertial>
      <origin xyz=".031720 .001070 -.000586"/>
      <mass value="0.057957"/>
      <inertia ixx="0.00000461" ixy="0.00000003" ixz="0.00000164" iyy="0.00003590" iyz="0.00000004" izz="0.00003682"/>
    </inertial>
    <collision>
      <origin rpy="3.14159265359 1.57079632679 0" xyz="0 0 0"/>
      <geometry>
        <mesh filename="package://apollo_robot_model/meshes/collision/secondFingerLink_smpl.stl"/>
      </geometry>
      <mu1 value="50000.0"/>
      <mu2 value="50000.0"/>
      <kp value="1000000.0"/>
      <kd value="1.0"/>
    </collision>
  </link>
  <gazebo reference="R_HAND_M_FINGER_KNUCKLE_2">
    <material>
                PR2/Grey2
            </material>
    <turnGravityOff>
                true
            </turnGravityOff>
    <selfCollide>
                true
            </selfCollide>
  </gazebo>
  <transmission name="DarmSim_RArm_BHand_FingerMKnuckleTwo_trans" type="pr2_mechanism_model/SimpleTransmission">
    <actuator name="DarmSim_RArm_BHand_FingerMKnuckleTwo_motor"/>
    <joint name="R_Arm_M_Finger_KnuckleTwoJoint"/>
    <mechanicalReduction>1</mechanicalReduction>
    <motorTorqueConstant>1</motorTorqueConstant>
    <pulsesPerRevolution>90000</pulsesPerRevolution>
  </transmission>
  <link name="R_HAND_M_FINGER_KNUCKLE_3">
    <visual>
      <material name="DarpaGrey"/>
      <origin rpy="0 1.57079632679 0" xyz="0 0 0"/>
      <geometry>
        <mesh filename="package://apollo_robot_model/meshes/thirdFingerLink.stl"/>
      </geometry>
    </visual>
    <inertial>
      <origin xyz="0.01970974 0.00182016 0.00020041"/>
      <mass value="0.03421781"/>
      <inertia ixx="0.00000287" ixy="0.00000091" ixz="-0.00000007" iyy="0.00001329" iyz="-0.00000002" izz="0.00001214"/>
    </inertial>
    <collision>
      <origin rpy="0 1.57079632679 0" xyz="0 0 0"/>
      <geometry>
        <mesh filename="package://apollo_robot_model/meshes/collision/thirdFingerLink_smpl.stl"/>
      </geometry>
      <mu1 value="50000.0"/>
      <mu2 value="50000.0"/>
      <kp value="1000000.0"/>
      <kd value="1.0"/>
    </collision>
  </link>
  <gazebo reference="R_HAND_M_FINGER_KNUCKLE_3">
    <material>
                PR2/Grey2
            </material>
    <turnGravityOff>
                true
            </turnGravityOff>
    <selfCollide>
                true
            </selfCollide>
  </gazebo>
  <transmission name="DarmSim_RArm_BHand_FingerMKnuckleThree_trans" type="pr2_mechanism_model/SimpleTransmission">
    <actuator name="DarmSim_RArm_BHand_FingerMKnuckleThree_motor"/>
    <joint name="R_Arm_M_Finger_KnuckleThreeJoint"/>
    <mechanicalReduction>1</mechanicalReduction>
    <motorTorqueConstant>1</motorTorqueConstant>
    <pulsesPerRevolution>90000</pulsesPerRevolution>
  </transmission>
  <link name="R_HAND_M_FINGER_TIP"/>
  <joint name="R_MF" type="revolute">
    <parent link="R_ARM_PALM"/>
    <child link="R_HAND_M_FINGER_KNUCKLE_2"/>
    <origin rpy="-1.57079632679 -0.0429350996 -1.57079632679" xyz="0 -0.05 0.09938"/>
    <axis xyz="0 0 -1"/>
    <limit effort="1" lower="0" upper="2.44" velocity="3.27"/>
    <dynamics damping="0.005" friction="100.0"/>
  </joint>
  <joint name="R_MF2" type="revolute">
    <parent link="R_HAND_M_FINGER_KNUCKLE_2"/>
    <child link="R_HAND_M_FINGER_KNUCKLE_3"/>
    <origin rpy="0 0 0" xyz="0.07 0 0"/>
    <!--<origin xyz="0.07 0 0" rpy="0 0 -0.733038286"/>-->
    <axis xyz="0 0 -1"/>
    <limit effort="1" lower="0.698131700798" upper="1.57079632679" velocity="3.27"/>
    <dynamics damping="0.005" friction="100.0"/>
    <!--<mimic joint="${side}_${number}F" multiplier="1" offset="0"/>-->
  </joint>
  <joint name="R_MF3" type="fixed">
    <parent link="R_HAND_M_FINGER_KNUCKLE_3"/>
    <child link="R_HAND_M_FINGER_TIP"/>
    <origin rpy="0 0 0" xyz="0.056 0 0"/>
  </joint>
  <link name="R_HAND_L_FINGER_KNUCKLE_1">
    <visual>
      <material name="DarpaGrey"/>
      <origin rpy="1.57079632679 0 -1.57079632679" xyz="0 0 0"/>
      <geometry>
        <mesh filename="package://apollo_robot_model/meshes/firstFingerLink.stl"/>
      </geometry>
      <mu1 value="50000.0"/>
      <mu2 value="50000.0"/>
      <kp value="1000000.0"/>
      <kd value="1.0"/>
    </visual>
    <inertial>
      <origin xyz="0.03201666 -0.00086502 0.00890075"/>
      <mass value="0.16252678"/>
      <inertia ixx="0.00002567" ixy="-0.00000146" ixz="0.00001128" iyy="0.00008818" iyz="-0.00000094" izz="0.00007827"/>
    </inertial>
    <collision>
      <origin rpy="1.57079632679 0 -1.57079632679" xyz="0 0 0"/>
      <geometry>
        <mesh filename="package://apollo_robot_model/meshes/collision/firstFingerLink_smpl.stl"/>
      </geometry>
    </collision>
  </link>
  <gazebo reference="R_HAND_L_FINGER_KNUCKLE_1">
    <material>
                PR2/Grey2
            </material>
    <turnGravityOff>
                true
            </turnGravityOff>
    <selfCollide>
                true
            </selfCollide>
  </gazebo>
  <transmission name="DarmSim_RArm_BHand_FingerOneKnuckleOne_trans" type="pr2_mechanism_model/SimpleTransmission">
    <actuator name="DarmSim_RArm_BHand_FingerOneKnuckleOne_motor"/>
    <joint name="R_Arm_FingerOne_KnuckleOneJoint"/>
    <mechanicalReduction>1</mechanicalReduction>
    <motorTorqueConstant>1</motorTorqueConstant>
    <pulsesPerRevolution>90000</pulsesPerRevolution>
  </transmission>
  <link name="R_HAND_L_FINGER_KNUCKLE_2">
    <visual>
      <material name="DarpaGrey"/>
      <origin rpy="3.14159265359 1.57079632679 0" xyz="0 0 0"/>
      <geometry>
        <mesh filename="package://apollo_robot_model/meshes/secondFingerLink.stl"/>
      </geometry>
    </visual>
    <inertial>
      <origin xyz=".031720 .001070 -.000586"/>
      <mass value="0.057957"/>
      <inertia ixx="0.00000461" ixy="0.00000003" ixz="0.00000164" iyy="0.00003590" iyz="0.00000004" izz="0.00003682"/>
    </inertial>
    <collision>
      <origin rpy="3.14159265359 1.57079632679 0" xyz="0 0 0"/>
      <geometry>
        <mesh filename="package://apollo_robot_model/meshes/collision/secondFingerLink_smpl.stl"/>
      </geometry>
      <mu1 value="50000.0"/>
      <mu2 value="50000.0"/>
      <kp value="1000000.0"/>
      <kd value="1.0"/>
    </collision>
  </link>
  <gazebo reference="R_HAND_L_FINGER_KNUCKLE_2">
    <material>
                PR2/Grey2
            </material>
    <turnGravityOff>
                true
            </turnGravityOff>
    <selfCollide>
                true
            </selfCollide>
  </gazebo>
  <transmission name="DarmSim_RArm_BHand_FingerLKnuckleTwo_trans" type="pr2_mechanism_model/SimpleTransmission">
    <actuator name="DarmSim_RArm_BHand_FingerLKnuckleTwo_motor"/>
    <joint name="R_Arm_L_Finger_KnuckleTwoJoint"/>
    <mechanicalReduction>1</mechanicalReduction>
    <motorTorqueConstant>1</motorTorqueConstant>
    <pulsesPerRevolution>90000</pulsesPerRevolution>
  </transmission>
  <link name="R_HAND_L_FINGER_KNUCKLE_3">
    <visual>
      <material name="DarpaGrey"/>
      <origin rpy="0 1.57079632679 0" xyz="0 0 0"/>
      <geometry>
        <mesh filename="package://apollo_robot_model/meshes/thirdFingerLink.stl"/>
      </geometry>
    </visual>
    <inertial>
      <origin xyz="0.01970974 0.00182016 0.00020041"/>
      <mass value="0.03421781"/>
      <inertia ixx="0.00000287" ixy="0.00000091" ixz="-0.00000007" iyy="0.00001329" iyz="-0.00000002" izz="0.00001214"/>
    </inertial>
    <collision>
      <origin rpy="0 1.57079632679 0" xyz="0 0 0"/>
      <geometry>
        <mesh filename="package://apollo_robot_model/meshes/collision/thirdFingerLink_smpl.stl"/>
      </geometry>
      <mu1 value="50000.0"/>
      <mu2 value="50000.0"/>
      <kp value="1000000.0"/>
      <kd value="1.0"/>
    </collision>
  </link>
  <gazebo reference="R_HAND_L_FINGER_KNUCKLE_3">
    <material>
                PR2/Grey2
            </material>
    <turnGravityOff>
                true
            </turnGravityOff>
    <selfCollide>
                true
            </selfCollide>
  </gazebo>
  <transmission name="DarmSim_RArm_BHand_FingerLKnuckleThree_trans" type="pr2_mechanism_model/SimpleTransmission">
    <actuator name="DarmSim_RArm_BHand_FingerLKnuckleThree_motor"/>
    <joint name="R_Arm_L_Finger_KnuckleThreeJoint"/>
    <mechanicalReduction>1</mechanicalReduction>
    <motorTorqueConstant>1</motorTorqueConstant>
    <pulsesPerRevolution>90000</pulsesPerRevolution>
  </transmission>
  <link name="R_HAND_L_FINGER_TIP"/>
  <joint name="R_LF" type="revolute">
    <parent link="R_HAND_L_FINGER_KNUCKLE_1"/>
    <child link="R_HAND_L_FINGER_KNUCKLE_2"/>
    <origin rpy="-1.57079632679 -0.0429350996 0" xyz=".05 0 0.02140"/>
    <axis xyz="0 0 -1"/>
    <limit effort="1" lower="0" upper="2.44" velocity="3.27"/>
    <dynamics damping="0.005" friction="100.0"/>
  </joint>
  <joint name="R_LF2" type="revolute">
    <parent link="R_HAND_L_FINGER_KNUCKLE_2"/>
    <child link="R_HAND_L_FINGER_KNUCKLE_3"/>
    <origin rpy="0 0 0" xyz="0.07 0 0"/>
    <!--<origin xyz="0.07 0 0" rpy="0 0 -0.733038286"/>-->
    <axis xyz="0 0 -1"/>
    <limit effort="1" lower="0.698131700798" upper="1.57079632679" velocity="3.27"/>
    <dynamics damping="0.005" friction="100.0"/>
    <!--<mimic joint="${side}_${number}F" multiplier="1" offset="0"/>-->
  </joint>
  <joint name="R_LF3" type="fixed">
    <parent link="R_HAND_L_FINGER_KNUCKLE_3"/>
    <child link="R_HAND_L_FINGER_TIP"/>
    <origin rpy="0 0 0" xyz="0.056 0 0"/>
  </joint>
  <link name="R_HAND_R_FINGER_KNUCKLE_1">
    <visual>
      <material name="DarpaGrey"/>
      <origin rpy="1.57079632679 0 -1.57079632679" xyz="0 0 0"/>
      <geometry>
        <mesh filename="package://apollo_robot_model/meshes/firstFingerLink.stl"/>
      </geometry>
    </visual>
    <inertial>
      <origin xyz="0.03201666 -0.00086502 0.00890075"/>
      <mass value="0.16252678"/>
      <inertia ixx="0.00002567" ixy="-0.00000146" ixz="0.00001128" iyy="0.00008818" iyz="-0.00000094" izz="0.00007827"/>
    </inertial>
    <collision>
      <origin rpy="1.57079632679 0 -1.57079632679" xyz="0 0 0"/>
      <geometry>
        <mesh filename="package://apollo_robot_model/meshes/collision/firstFingerLink_smpl.stl"/>
      </geometry>
    </collision>
  </link>
  <gazebo reference="R_HAND_R_FINGER_KNUCKLE_1">
    <material>
                PR2/Grey2
            </material>
    <turnGravityOff>
                true
            </turnGravityOff>
    <selfCollide>
                true
            </selfCollide>
  </gazebo>
  <transmission name="DarmSim_RArm_BHand_FingerTwoKnuckleOne_trans" type="pr2_mechanism_model/SimpleTransmission">
    <actuator name="DarmSim_RArm_BHand_FingerTwoKnuckleOne_motor"/>
    <joint name="R_Arm_FingerTwo_KnuckleOneJoint"/>
    <mechanicalReduction>1</mechanicalReduction>
    <motorTorqueConstant>1</motorTorqueConstant>
    <pulsesPerRevolution>90000</pulsesPerRevolution>
  </transmission>
  <link name="R_HAND_R_FINGER_KNUCKLE_2">
    <visual>
      <material name="DarpaGrey"/>
      <origin rpy="3.14159265359 1.57079632679 0" xyz="0 0 0"/>
      <geometry>
        <mesh filename="package://apollo_robot_model/meshes/secondFingerLink.stl"/>
      </geometry>
    </visual>
    <inertial>
      <origin xyz=".031720 .001070 -.000586"/>
      <mass value="0.057957"/>
      <inertia ixx="0.00000461" ixy="0.00000003" ixz="0.00000164" iyy="0.00003590" iyz="0.00000004" izz="0.00003682"/>
    </inertial>
    <collision>
      <origin rpy="3.14159265359 1.57079632679 0" xyz="0 0 0"/>
      <geometry>
        <mesh filename="package://apollo_robot_model/meshes/collision/secondFingerLink_smpl.stl"/>
      </geometry>
      <mu1 value="50000.0"/>
      <mu2 value="50000.0"/>
      <kp value="1000000.0"/>
      <kd value="1.0"/>
    </collision>
  </link>
  <gazebo reference="R_HAND_R_FINGER_KNUCKLE_2">
    <material>
                PR2/Grey2
            </material>
    <turnGravityOff>
                true
            </turnGravityOff>
    <selfCollide>
                true
            </selfCollide>
  </gazebo>
  <transmission name="DarmSim_RArm_BHand_FingerRKnuckleTwo_trans" type="pr2_mechanism_model/SimpleTransmission">
    <actuator name="DarmSim_RArm_BHand_FingerRKnuckleTwo_motor"/>
    <joint name="R_Arm_R_Finger_KnuckleTwoJoint"/>
    <mechanicalReduction>1</mechanicalReduction>
    <motorTorqueConstant>1</motorTorqueConstant>
    <pulsesPerRevolution>90000</pulsesPerRevolution>
  </transmission>
  <link name="R_HAND_R_FINGER_KNUCKLE_3">
    <visual>
      <material name="DarpaGrey"/>
      <origin rpy="0 1.57079632679 0" xyz="0 0 0"/>
      <geometry>
        <mesh filename="package://apollo_robot_model/meshes/thirdFingerLink.stl"/>
      </geometry>
    </visual>
    <inertial>
      <origin xyz="0.01970974 0.00182016 0.00020041"/>
      <mass value="0.03421781"/>
      <inertia ixx="0.00000287" ixy="0.00000091" ixz="-0.00000007" iyy="0.00001329" iyz="-0.00000002" izz="0.00001214"/>
    </inertial>
    <collision>
      <origin rpy="0 1.57079632679 0" xyz="0 0 0"/>
      <geometry>
        <mesh filename="package://apollo_robot_model/meshes/collision/thirdFingerLink_smpl.stl"/>
      </geometry>
      <mu1 value="50000.0"/>
      <mu2 value="50000.0"/>
      <kp value="1000000.0"/>
      <kd value="1.0"/>
    </collision>
  </link>
  <gazebo reference="R_HAND_R_FINGER_KNUCKLE_3">
    <material>
                PR2/Grey2
            </material>
    <turnGravityOff>
                true
            </turnGravityOff>
    <selfCollide>
                true
            </selfCollide>
  </gazebo>
  <transmission name="DarmSim_RArm_BHand_FingerRKnuckleThree_trans" type="pr2_mechanism_model/SimpleTransmission">
    <actuator name="DarmSim_RArm_BHand_FingerRKnuckleThree_motor"/>
    <joint name="R_Arm_R_Finger_KnuckleThreeJoint"/>
    <mechanicalReduction>1</mechanicalReduction>
    <motorTorqueConstant>1</motorTorqueConstant>
    <pulsesPerRevolution>90000</pulsesPerRevolution>
  </transmission>
  <link name="R_HAND_R_FINGER_TIP"/>
  <joint name="R_RF" type="revolute">
    <parent link="R_HAND_R_FINGER_KNUCKLE_1"/>
    <child link="R_HAND_R_FINGER_KNUCKLE_2"/>
    <origin rpy="-1.57079632679 -0.0429350996 0" xyz=".05 0 0.02140"/>
    <axis xyz="0 0 -1"/>
    <limit effort="1" lower="0" upper="2.44" velocity="3.27"/>
    <dynamics damping="0.005" friction="100.0"/>
  </joint>
  <joint name="R_RF2" type="revolute">
    <parent link="R_HAND_R_FINGER_KNUCKLE_2"/>
    <child link="R_HAND_R_FINGER_KNUCKLE_3"/>
    <origin rpy="0 0 0" xyz="0.07 0 0"/>
    <!--<origin xyz="0.07 0 0" rpy="0 0 -0.733038286"/>-->
    <axis xyz="0 0 -1"/>
    <limit effort="1" lower="0.698131700798" upper="1.57079632679" velocity="3.27"/>
    <dynamics damping="0.005" friction="100.0"/>
    <!--<mimic joint="${side}_${number}F" multiplier="1" offset="0"/>-->
  </joint>
  <joint name="R_RF3" type="fixed">
    <parent link="R_HAND_R_FINGER_KNUCKLE_3"/>
    <child link="R_HAND_R_FINGER_TIP"/>
    <origin rpy="0 0 0" xyz="0.056 0 0"/>
  </joint>
  <joint name="R_FR" type="revolute">
    <parent link="R_ARM_PALM"/>
    <child link="R_HAND_L_FINGER_KNUCKLE_1"/>
    <origin rpy="0 0 1.57079632679" xyz=".02497 0 0.07798"/>
    <axis xyz="0 0 -1"/>
    <limit effort="1" lower="0" upper="3.14159265359" velocity="3.27"/>
    <dynamics damping="0.005" friction="100.0"/>
  </joint>
  <joint name="R_FR2" type="revolute">
    <parent link="R_ARM_PALM"/>
    <child link="R_HAND_R_FINGER_KNUCKLE_1"/>
    <origin rpy="0 0 1.57079632679" xyz="-.02497 0 0.07798"/>
    <axis xyz="0 0 1"/>
    <limit effort="1" lower="0" upper="3.14159265359" velocity="3.27"/>
    <dynamics damping="0.005" friction="100.0"/>
    <mimic joint="R_FR" multiplier="1" offset="0"/>
  </joint>
  <!-- Adding Apollo's Head-->
  <joint name="B_STAND_MOTORS" type="fixed">
    <origin rpy="0 0 0" xyz="0 0.15 -0.25"/>
    <parent link="BASE"/>
    <child link="B_MOTORS"/>
  </joint>
  <link name="B_MOTORS">
    <visual>
      <material name="DarpaGrey"/>
      <origin rpy="0 0 0" xyz="0.0 0.05 -0.06"/>
      <geometry>
        <box size="0.2 0.15 0.12 "/>
      </geometry>
    </visual>
    <collision>
      <origin rpy="0 0 0" xyz="0.0 0.05 -0.06"/>
      <geometry>
        <box size="0.2 0.15 0.12 "/>
      </geometry>
    </collision>
  </link>
  <joint name="B_MOTORS_neck" type="fixed">
    <origin rpy="0 0 0" xyz="0 0 0"/>
    <parent link="B_MOTORS"/>
    <child link="B_CERVICALS"/>
  </joint>
  <link name="B_CERVICALS">
    <visual>
      <material name="DarpaGrey"/>
      <origin rpy="0 0 0" xyz="0 0 0.19685"/>
      <geometry>
        <cylinder length="0.3937" radius="0.03"/>
      </geometry>
    </visual>
    <collision>
      <origin rpy="0 0 0" xyz="0 0 0.19685"/>
      <geometry>
        <cylinder length="0.3937" radius="0.03"/>
      </geometry>
    </collision>
  </link>
  <joint name="B_NECK" type="fixed">
    <origin rpy="-1.57079632679 0 1.57079632679" xyz="0.0 0.15 0.1437"/>
    <parent link="BASE"/>
    <child link="B_NECK"/>
  </joint>
  <link name="B_NECK"/>
  <joint name="B_HN" type="revolute">
    <parent link="B_NECK"/>
    <child link="B_CERVICAL1"/>
    <origin rpy="0 0 0" xyz="0 0 0"/>
    <axis xyz="0 0 1"/>
    <dynamics damping="25"/>
    <limit effort="200" lower="-0.522812" upper="0.525297" velocity="1.9634"/>
  </joint>
  <link name="B_CERVICAL1"/>
  <joint name="B_HT" type="revolute">
    <parent link="B_CERVICAL1"/>
    <child link="B_CERVICAL2"/>
    <origin rpy="0 1.57079632679 0" xyz="0 0 0"/>
    <axis xyz="0 0 1"/>
    <dynamics damping="25"/>
    <limit effort="200" lower="-0.283485" upper="0.342839" velocity="1.9634"/>
  </joint>
  <link name="B_CERVICAL2"/>
  <joint name="B_HR" type="revolute">
    <parent link="B_CERVICAL2"/>
    <child link="B_HEAD"/>
    <origin rpy="-1.57079632679 0 0" xyz="0 0 0"/>
    <axis xyz="0 0 1"/>
    <dynamics damping="25"/>
    <limit effort="200" lower="-1.013835" upper="0.892918" velocity="1.9634"/>
  </joint>
  <link name="B_HEAD">
    <inertial>
      <origin rpy="0 0 0" xyz="0 0 0"/>
      <mass value="1.0"/>
      <inertia ixx="0.01" ixy="0" ixz="0" iyy="0.01" iyz="0" izz="0.01"/>
    </inertial>
    <visual>
      <material name="DarpaGrey"/>
      <origin rpy="-1.57079632679 0 0" xyz="-0.035 -0.065 -0.08"/>
      <geometry>
        <mesh filename="package://apollo_robot_model/meshes/humanoidHead.stl"/>
      </geometry>
    </visual>
    <collision>
      <origin rpy="-1.57079632679 0 0" xyz="-0.035 -0.065 -0.08"/>
      <geometry>
        <mesh filename="package://apollo_robot_model/meshes/collision/humanoidHead_smpl.stl"/>
      </geometry>
    </collision>
  </link>
  <joint name="R_EP" type="revolute">
    <parent link="B_HEAD"/>
    <child link="R_PAN_UNIT"/>
    <origin rpy="0 0 0" xyz="0.0366 -0.0674 -0.1356"/>
    <axis xyz="0 0 1"/>
    <dynamics damping="25"/>
    <limit effort="200" lower="-0.547836" upper="0.677454" velocity="1.9634"/>
  </joint>
  <link name="R_PAN_UNIT"/>
  <joint name="R_ET" type="revolute">
    <parent link="R_PAN_UNIT"/>
    <child link="R_EYE"/>
    <origin rpy="0 -1.57079632679 0" xyz="0 0 0"/>
    <axis xyz="0 0 1"/>
    <dynamics damping="25"/>
    <limit effort="200" lower="-0.584609" upper="0.667224" velocity="1.9634"/>
  </joint>
  <link name="R_EYE">
    <inertial>
      <origin rpy="0 0 0" xyz="0 0 0"/>
      <mass value="1.0"/>
      <inertia ixx="0.01" ixy="0" ixz="0" iyy="0.01" iyz="0" izz="0.01"/>
    </inertial>
    <visual>
      <material name="DarpaGrey"/>
      <origin rpy="0 1.57079632679 1.57079632679" xyz="0.0545 0 0.072"/>
      <geometry>
        <mesh filename="package://apollo_robot_model/meshes/humanoidHeadRightEye.stl"/>
      </geometry>
    </visual>
    <!--
      <collision>
	<origin xyz="0.0545 0 0.072" rpy="0 ${PI/2.0} ${PI/2.0}"/>
	<geometry>
	  <mesh filename="package://apollo_robot_model/meshes/collision/humanoidHeadRightEye.stl" />
	</geometry>
      </collision>
      -->
  </link>
  <joint name="R_E_UPPER" type="fixed">
    <parent link="R_EYE"/>
    <child link="R_EYE_UPPER"/>
    <origin rpy="0 0 0" xyz="0 -0.023 0"/>
  </joint>
  <link name="R_EYE_UPPER">
    <inertial>
      <origin rpy="0 0 0" xyz="0 0 0"/>
      <mass value="1.0"/>
      <inertia ixx="0.01" ixy="0" ixz="0" iyy="0.01" iyz="0" izz="0.01"/>
    </inertial>
    <visual>
      <material name="DarpaGrey"/>
      <origin rpy="0 1.57079632679 1.57079632679" xyz="0 0 0"/>
      <geometry>
        <cylinder length="0.001" radius="0.007"/>
      </geometry>
    </visual>
  </link>
  <joint name="R_E_LOWER" type="fixed">
    <parent link="R_EYE"/>
    <child link="R_EYE_LOWER"/>
    <origin rpy="0 0 0" xyz="0.017 -0.021 0"/>
  </joint>
  <link name="R_EYE_LOWER">
    <inertial>
      <origin rpy="0 0 0" xyz="0 0 0"/>
      <mass value="1.0"/>
      <inertia ixx="0.01" ixy="0" ixz="0" iyy="0.01" iyz="0" izz="0.01"/>
    </inertial>
    <visual>
      <material name="DarpaGrey"/>
      <origin rpy="0 1.57079632679 1.57079632679" xyz="0 0 0"/>
      <geometry>
        <cylinder length="0.01" radius="0.006"/>
      </geometry>
    </visual>
  </link>
  <joint name="L_EP" type="revolute">
    <parent link="B_HEAD"/>
    <child link="L_PAN_UNIT"/>
    <origin rpy="0 0 0" xyz="-0.0366 -0.0674 -0.1356"/>
    <axis xyz="0 0 1"/>
    <dynamics damping="25"/>
    <limit effort="200" lower="-0.557414" upper="0.697715" velocity="1.9634"/>
  </joint>
  <link name="L_PAN_UNIT"/>
  <joint name="L_ET" type="revolute">
    <parent link="L_PAN_UNIT"/>
    <child link="L_EYE"/>
    <origin rpy="0 -1.57079632679 0" xyz="0 0 0"/>
    <axis xyz="0 0 1"/>
    <dynamics damping="25"/>
    <limit effort="200" lower="-0.574821" upper="0.626982" velocity="1.9634"/>
  </joint>
  <link name="L_EYE">
    <inertial>
      <origin rpy="0 0 0" xyz="0 0 0"/>
      <mass value="1.0"/>
      <inertia ixx="0.01" ixy="0" ixz="0" iyy="0.01" iyz="0" izz="0.01"/>
    </inertial>
    <visual>
      <material name="DarpaGrey"/>
      <origin rpy="0 1.57079632679 1.57079632679" xyz="0.0545 0 0.072"/>
      <geometry>
        <mesh filename="package://apollo_robot_model/meshes/humanoidHeadRightEye.stl"/>
      </geometry>
    </visual>
    <!--
      <collision>
	<origin xyz="0.0545 0 0.072" rpy="0 ${PI/2.0} ${PI/2.0}"/>
	<geometry>
	  <mesh filename="package://apollo_robot_model/meshes/collision/humanoidHeadRightEye.stl" />
	</geometry>
      </collision>
      -->
  </link>
  <joint name="L_E_UPPER" type="fixed">
    <parent link="L_EYE"/>
    <child link="L_EYE_UPPER"/>
    <origin rpy="0 0 0" xyz="0 -0.023 0"/>
  </joint>
  <link name="L_EYE_UPPER">
    <inertial>
      <origin rpy="0 0 0" xyz="0 0 0"/>
      <mass value="1.0"/>
      <inertia ixx="0.01" ixy="0" ixz="0" iyy="0.01" iyz="0" izz="0.01"/>
    </inertial>
    <visual>
      <material name="DarpaGrey"/>
      <origin rpy="0 1.57079632679 1.57079632679" xyz="0 0 0"/>
      <geometry>
        <cylinder length="0.001" radius="0.007"/>
      </geometry>
    </visual>
  </link>
  <joint name="L_E_LOWER" type="fixed">
    <parent link="L_EYE"/>
    <child link="L_EYE_LOWER"/>
    <origin rpy="0 0 0" xyz="0.017 -0.021 0"/>
  </joint>
  <link name="L_EYE_LOWER">
    <inertial>
      <origin rpy="0 0 0" xyz="0 0 0"/>
      <mass value="1.0"/>
      <inertia ixx="0.01" ixy="0" ixz="0" iyy="0.01" iyz="0" izz="0.01"/>
    </inertial>
    <visual>
      <material name="DarpaGrey"/>
      <origin rpy="0 1.57079632679 1.57079632679" xyz="0 0 0"/>
      <geometry>
        <cylinder length="0.01" radius="0.006"/>
      </geometry>
    </visual>
  </link>
</robot>

